Micky G, [10.05.21 15:40]
<?xml version='1.0'?>
<sdf version='1.6'>
    <model name='arx'>
        <link name='base'>
            <pose>0 0 .05 0 0 0</pose>

            <collision name='collision'>
                <geometry>
                    <cylinder>
                        <radius>.5</radius>
                        <length>.1</length>
                    </cylinder>
                    
                </geometry>
            </collision>
            <visual name='visual'>
                <geometry>
                    <cylinder>
                        <radius>.5</radius>
                        <length>.1</length>
                    </cylinder>
                   
                </geometry>
            </visual>
        </link> -->

        <link name='arm1'>
            <pose>0 0 0.125 0 0 0</pose>

            <collision name='collision'>
                <geometry>
                    <cylinder>
                        <radius>.1</radius>
                        <length>.05</length>
                    </cylinder>
                </geometry>
            </collision>
            <visual name='visual'>
                <geometry>
                    <cylinder>
                        <radius>.1</radius>
                        <length>.05</length>
                    </cylinder>
                </geometry>
            </visual>
        </link>

        <link name='arm2'>
            <pose>0 0 1.15 0 0 0</pose>

            <collision name='collision'>
                <geometry>
                    <cylinder>
                        <radius>.05</radius>
                        <length>2</length>
                    </cylinder>
                </geometry>
            </collision>
            <visual name='visual'>
                <geometry>
                    <cylinder>
                        <radius>.05</radius>
                        <length>2</length>
                    </cylinder>
                </geometry>
            </visual>
        </link>

        <joint name="base_arm1" type="revolute">
            <parent>base</parent>
            <child>arm1</child>
            <pose>0 0 -0.025 0 0 0</pose>
            <axis>
                <xyz>0 0 1</xyz>
            </axis>
        </joint>

        <joint name="base_arm2" type="revolute">
            <parent>arm1</parent>
            <child>arm2</child>
            <pose>0 0 -1 0 0 0</pose>
            <axis>
                <xyz>0 1 0</xyz>
            </axis>
        </joint>
    </model>
</sdf>